Workbook
Name NativeTimeline_Order_Date: #N/A
Name Slicer_Category: #N/A
Name Slicer_Region: #N/A

Sheet Raw Data
A1: Row ID | B1: Order ID | C1: Order Date | D1: Ship Date | E1: Ship Mode | F1: Customer ID | G1: Customer Name | H1: Segment | I1: Country | J1: City | K1: State | L1: Region | M1: Postal Code | N1: Product ID | O1: Category | P1: Sub-Category | Q1: Product Name | R1: Sales | S1: Quantity | T1: Discount | U1: Profit | W1: =$U$1 -> Profit
A2: 1595 | B2: ORD-2024-00595 | C2: 45334 | D2: 45339 | E2: Standard Class | F2: CUST-1089 | G2: Nikhil Varma | H2: Corporate | I2: India | J2: Bhubaneswar | K2: Odisha | L2: East | M2: 682001 | N2: P-235 | O2: Clothing | P2: Shirts | Q2: Cotton Casual Shirt | R2: 2439.75 | S2: 2 | T2: 0.1 | U2: 498.33 | W2: =$U$1 -> Profit
A3: 1098 | B3: ORD-2024-00098 | C3: 45577 | D3: 45580 | E3: Standard Class | F3: CUST-1102 | G3: Amal Thomas | H3: Consumer | I3: India | J3: Ahmedabad | K3: Gujarat | L3: South | M3: 695001 | N3: P-649 | O3: Electronics | P3: Mobiles | Q3: Samsung Galaxy A55 | R3: 184132.26 | S3: 7 | T3: 0.25 | U3: -8938.1 | W3: =$U$1 -> Profit
A4: 1282 | B4: ORD-2024-00282 | C4: 45480 | D4: 45482 | E4: First Class | F4: CUST-1099 | G4: Ananya Menon | H4: Consumer | I4: India | J4: Delhi | K4: Delhi | L4: south | M4: 682001 | N4: P-858 | O4: Furniture | P4: Tables | Q4: Study Table | R4: 32210.22 | S4: 5 | T4: 0.05 | U4: 3109.97 | W4: =$U$1 -> Profit
A5: 1658 | B5: ORD-2024-00658 | C5: 45508 | D5: 45514 | E5: Standard Class | F5: CUST-1026 | G5: Rahul Kumar | H5: Consumer | I5: India | J5: Hyderabad | K5: Telangana | L5: North | M5: 682001 | N5: P-129 | O5: Furniture | P5: Chairs | Q5: Ergonomic Office Chair | R5: 18979.09 | S5: 3 | T5: 0.25 | U5: -50.85 | W5: =$U$1 -> Profit
A6: 1586 | B6: ORD-2024-00586 | C6: 45546 | D6: 45548 | E6: Second Class | F6: CUST-1086 | G6: Muhammed Shafi | H6: Corporate | I6: India | J6: Bengaluru | K6: Karnataka | L6: South | M6: 673001 | N6: P-760 | O6: Electronics | P6: Mobiles | Q6: Samsung Galaxy A55 | R6: 102685.8 | S6: 25 | T6: 0.3 | U6: -10828.26
A7: 1079 | B7: ORD-2024-00079 | C7: 45396 | D7: 45399 | E7: Second Class | F7: CUST-1119 | G7: Arjun Das | H7: Consumer | I7: India | J7: Jaipur | K7: Rajasthan | L7: East | M7: 400001 | N7: P-596 | O7: Clothing | P7: Shoes | Q7: Running Shoes | R7: 6576.27 | S7: 2 | T7: 0 | U7: 1859.13
A8: 1055 | B8: ORD-2024-00055 | C8: 45480 | D8: 45482 | E8: Standard Class | F8: CUST-1100 | G8: Riya Paul | H8: corporate | I8: India | J8: Lucknow | K8: Uttar Pradesh | L8: West | M8: 695001 | N8: P-210 | O8: electronics | P8: Mobiles | Q8: Samsung Galaxy A55 | R8: 29272.2 | S8: 1 | T8: 0.15 | U8: 288.51
A9: 1110 | B9: ORD-2024-00110 | C9: 45329 | D9: 45330 | E9: First Class | F9: CUST-1078 | G9: Rahul Kumar | H9: Consumer | I9: India | J9: Hyderabad | K9: Telangana | L9: south | M9: 682001 | N9: P-381 | O9: Furniture | P9: Bookcases | Q9: Wooden Bookshelf | R9: 4587.26 | S9: 1 | T9: 0.3 | U9: -188.59
A10: 1325 | B10: ORD-2024-00325 | C10: 45298 | D10: 45304 | E10: Same Day | F10: CUST-1015 | G10: Amal Thomas | H10: Corporate | I10: India | J10: Delhi | K10: Delhi | L10: west | M10: 682001 | N10: P-680 | O10: Furniture | P10: Bookcases | Q10: Wooden Bookshelf | R10: 23436.39 | S10: 5 | T10: 0.3 | U10: -819.63 | W10: Running Shoes
A11: 1502 | B11: ORD-2024-00502 | C11: 45405 | D11: 45411 | E11: Second Class | F11: CUST-1097 | G11: Fathima Ali | H11: Home Office | I11: India | J11: Pune | K11: Maharashtra | L11: South | M11: 682001 | N11: P-549 | O11: Clothing | P11: Shoes | Q11: Running Shoes | R11: 15259.27 | S11: 6 | T11: 0.25 | U11: 1490.22 | W11: =_xlfn.XLOOKUP(Q7,Q:Q,N:N) -> P-596
A12: 1040 | B12: ORD-2024-00040 | C12: 45638 | D12: 45644 | E12: Second Class | F12: CUST-1079 | G12: Diya Mathew | H12: Consumer | I12: India | J12: Chennai | K12: Tamil Nadu | L12: North | M12: 560001 | N12: P-661 | O12: office supplies | P12: Binders | Q12: Office Binder Pack | R12: 952.92 | S12: 2 | T12: 0.25 | U12: 28.87
A13: 1665 | B13: ORD-2024-00665 | C13: 45421 | D13: 45426 | E13: Same Day | F13: CUST-1040 | G13: Adil Khan | H13: home office | I13: India | J13: Lucknow | K13: Uttar Pradesh | L13: North | M13: 110001 | N13: P-801 | O13: Clothing | P13: Shoes | Q13: Running Shoes | R13: 11812.53 | S13: 4 | T13: 0.1 | U13: 2183.35
A14: 1540 | B14: ORD-2024-00540 | C14: 45514 | D14: 45519 | E14: First Class | F14: CUST-1070 | G14: Nikhil Varma | H14: Consumer | I14: India | J14: Kochi | K14: Kerala | L14: West | M14: 682001 | N14: P-778 | O14: Furniture | P14: Tables | Q14: Study Table | R14: 20626.29 | S14: 4 | T14: 0.25 | U14: -63.17
A15: 1640 | B15: ORD-2024-00640 | C15: 45474 | D15: 45478 | E15: Same Day | F15: CUST-1063 | G15: Vishnu Raj | H15: Corporate | I15: India | J15: Bhubaneswar | K15: Odisha | L15: North | M15: 682001 | N15: P-886 | O15: Office Supplies | P15: Storage | Q15: Document Organizer | R15: 2686.98 | S15: 4 | T15: 0.25 | U15: 100.71
A16: 1600 | B16: ORD-2024-00600 | C16: 45381 | D16: 45387 | E16: Standard Class | F16: CUST-1072 | G16: Nikhil Varma | H16: Consumer | I16: India | J16: Pune | K16: Maharashtra | L16: west | M16: 682001 | N16: P-442 | O16: furniture | P16: Tables | Q16: Study Table | R16: 5990.08 | S16: 1 | T16: 0.2 | U16: 146.47
A17: 1335 | B17: ORD-2024-00335 | C17: 45534 | D17: 45536 | E17: Second Class | F17: CUST-1077 | G17: Asha Krishnan | H17: Consumer | I17: India | J17: Pune | K17: Maharashtra | L17: South | M17: 682001 | N17: P-358 | O17: Office Supplies | P17: Binders | Q17: Office Binder Pack | R17: 3087.01 | S17: 5 | T17: 0 | U17: 551.06
A18: 1255 | B18: ORD-2024-00255 | C18: 45334 | D18: 45339 | E18: Standard Class | F18: CUST-1102 | G18: Asha Krishnan | H18: Corporate | I18: India | J18: Ahmedabad | K18: Gujarat | L18: West | M18: 695001 | N18: P-133 | O18: Furniture | P18: Bookcases | Q18: Wooden Bookshelf | R18: 13035.13 | S18: 2 | T18: 0.05 | U18: 1849.55
A19: 1638 | B19: ORD-2024-00638 | C19: 45647 | D19: 45652 | E19: Standard Class | F19: CUST-1095 | G19: Muhammed Shafi | H19: consumer | I19: India | J19: Lucknow | K19: Uttar Pradesh | L19: West | M19: 673001 | N19: P-472 | O19: Office Supplies | P19: Art | Q19: Marker Set | R19: 284.11 | S19: 1 | T19: 0.25 | U19: 8.55
A20: 1219 | B20: ORD-2024-00219 | C20: 45560 | D20: 45561 | E20: Standard Class | F20: CUST-1105 | G20: Adil Khan | H20: Consumer | I20: India | J20: Kolkata | K20: West Bengal | L20: South | M20: 110001 | N20: P-106 | O20: Office Supplies | P20: Binders | Q20: Office Binder Pack | R20: 3633.4 | S20: 6 | T20: 0 | U20: 843.62
A21: 1537 | B21: ORD-2024-00537 | C21: 45524 | D21: 45528 | E21: Standard Class | F21: CUST-1009 | G21: Sneha Nair | H21: Home Office | I21: India | J21: Thiruvananthapuram | K21: Kerala | L21: South | M21: 695001 | N21: P-590 | O21: Clothing | P21: Shirts | Q21: Cotton Casual Shirt | R21: 2075.89 | S21: 2 | T21: 0.2 | U21: 189.06
A22: 1351 | B22: ORD-2024-00351 | C22: 45484 | D22: 45490 | E22: First Class | F22: CUST-1099 | G22: Vishnu Raj | H22: Consumer | I22: India | J22: Thiruvananthapuram | K22: Kerala | L22: SOUTH | M22: 600001 | N22: P-149 | O22: Electronics | P22: Mobiles | Q22: Samsung Galaxy A55 | R22: 144750.86 | S22: 4 | T22: 0 | U22: 12354.53
A23: 1723 | B23: ORD-2024-00723 | C23: 45485 | D23: 45490 | E23: Second Class | F23: CUST-1014 | G23: Meera Joseph | H23: Corporate | I23: India | J23: Chennai | K23: Tamil Nadu | L23: West | M23: 110001 | N23: P-897 | O23: Office Supplies | P23: Art | Q23: Marker Set | R23: 1529.06 | S23: 4 | T23: 0.05 | U23: 214.77
... A25: 1287 | B25: ORD-2024-00287 | C25: 45571 | D25: 45573 | E25: Second Class | F25: CUST-1001 | G25: Muhammed Shafi | H25: Consumer | I25: India | J25: Bengaluru | K25: Karnataka | L25: East | M25: 673001 | N25: P-338 | O25: Office Supplies | P25: Paper | Q25: A4 Copier Paper | R25: 3186.37 | S25: 8 | T25: 0.1 | U25: 456.42
A26: 1592 | B26: ORD-2024-00592 | C26: 45587 | D26: 45592 | E26: Second Class | F26: CUST-1012 | G26: Amal Thomas | H26: Consumer | I26: India | J26: Bengaluru | K26: Karnataka | L26: east | M26: 110001 | N26: P-321 | O26: Home Appliances | P26: Kitchen | Q26: Mixer Grinder | R26: 5626.92 | S26: 1 | T26: 0.05
A27: 1435 | B27: ORD-2024-00435 | C27: 45493 | D27: 45499 | E27: Second Class | F27: CUST-1059 | G27: Ananya Menon | H27: Consumer | I27: India | J27: Bhubaneswar | K27: Odisha | L27: East | M27: 695001 | N27: P-805 | O27: Furniture | P27: Bookcases | Q27: Wooden Bookshelf | R27: 16249.12 | S27: 3 | T27: 0.2 | U27: 596.21
A28: 1382 | B28: ORD-2024-00382 | C28: 45576 | D28: 45579 | E28: Second Class | F28: CUST-1021 | G28: Diya Mathew | H28: Consumer | I28: India | J28: Kolkata | K28: West Bengal | L28: North | M28: 673001 | N28: P-438 | O28: Office Supplies | P28: Binders | Q28: Office Binder Pack | R28: 530.27 | S28: 1 | T28: 0.15 | U28: 60.98
A29: 1369 | B29: ORD-2024-00369 | C29: 45473 | D29: 45479 | E29: First Class | F29: CUST-1071 | G29: Vishnu Raj | H29: Corporate | I29: India | J29: Kochi | K29: Kerala | L29: North | M29: 400001 | N29: P-208 | O29: Electronics | P29: Mobiles | Q29: Samsung Galaxy A55 | R29: 28304.39 | S29: 1 | T29: 0.2 | U29: -655.7
A30: 1702 | B30: ORD-2024-00702 | C30: 45522 | D30: 45527 | E30: Second Class | F30: CUST-1026 | G30: Arjun Das | H30: consumer | I30: India | J30: Kolkata | K30: West Bengal | L30: East | M30: 673001 | N30: P-441 | O30: Clothing | P30: Shirts | Q30: Cotton Casual Shirt | R30: 3888.64 | S30: 3 | T30: 0 | U30: 1087.07
A31: 1175 | B31: ORD-2024-00175 | C31: 45318 | D31: 45323 | E31: Second Class | F31: CUST-1047 | G31: Vishnu Raj | H31: corporate | I31: India | J31: Kolkata | K31: West Bengal | L31: North | M31: 673001 | N31: P-495 | O31: Furniture | P31: Tables | Q31: Study Table | R31: 10583.33 | S31: 2 | T31: 0.25 | U31: -28.12
A32: 1471 | B32: ORD-2024-00471 | C32: 45332 | D32: 45336 | E32: Standard Class | F32: CUST-1047 | G32: Vishnu Raj | H32: Home Office | I32: India | J32: Kochi | K32: Kerala | L32: east | M32: 110001 | N32: P-477 | O32: Electronics | P32: Laptops | Q32: Dell Inspiron 15 | R32: 35084.1 | S32: 1 | T32: 0.3 | U32: -3062.93
A33: 1581 | B33: ORD-2024-00581 | C33: 45504 | D33: 45506 | E33: First Class | F33: CUST-1071 | G33: Rahul Kumar | H33: Consumer | I33: India | J33: Jaipur | K33: Rajasthan | L33: East | M33: 682001 | N33: P-695 | O33: Electronics | P33: Accessories | Q33: Logitech Wireless Mouse | R33: 1199.43 | S33: 1 | T33: 0.05 | U33: 75.71
A34: 1156 | B34: ORD-2024-00156 | C34: 45471 | D34: 45475 | E34: Standard Class | F34: CUST-1094 | G34: Riya Paul | H34: Corporate | I34: India | J34: Chennai | K34: Tamil Nadu | L34: north | M34: 600001 | N34: P-545 | O34: Office Supplies | P34: Paper | Q34: A4 Copier Paper | R34: 623.85 | S34: 2 | T34: 0.3 | U34: 2.46
A35: 1121 | B35: ORD-2024-00121 | C35: 45315 | D35: 45317 | E35: Same Day | F35: CUST-1077 | G35: Aarav Nair | H35: Corporate | I35: India | J35: Kochi | K35: Kerala | L35: SOUTH | M35: 682001 | N35: P-408 | O35: Furniture | P35: Chairs | Q35: Ergonomic Office Chair | R35: 23202.51 | S35: 3 | T35: 0.15 | U35: 1779.29
A36: 1353 | B36: ORD-2024-00353 | C36: 45507 | D36: 45513 | E36: Standard Class | F36: CUST-1085 | G36: Vishnu Raj | H36: Corporate | I36: India | J36: Thiruvananthapuram | K36: Kerala | L36: North | M36: 600001 | N36: P-720 | O36: Electronics | P36: Accessories | Q36: HP Wireless Keyboard | R36: 4269.34 | S36: 3 | T36: 0.15 | U36: 66.44
A37: 1399 | B37: ORD-2024-00399 | C37: 45452 | D37: 45454 | E37: Second Class | F37: CUST-1092 | G37: Nikhil Varma | H37: Consumer | I37: India | J37: Mumbai | K37: Maharashtra | L37: East | M37: 695001 | N37: P-960 | O37: Clothing | P37: Shoes | Q37: Running Shoes | R37: 6842.49 | S37: 2 | T37: 0 | U37: 1766.33
A38: 1232 | B38: ORD-2024-00232 | C38: 45521 | D38: 45526 | E38: Same Day | F38: CUST-1014 | G38: Aarav Nair | H38: Consumer | I38: India | J38: Bhubaneswar | K38: Odisha | L38: South | M38: 695001 | N38: P-667 | O38: Furniture | P38: Chairs | Q38: Ergonomic Office Chair | R38: 6625.97 | S38: 1 | T38: 0.25 | U38: -17.26
A39: 1716 | B39: ORD-2024-00716 | C39: 45335 | D39: 45338 | E39: First Class | F39: CUST-1052 | G39: Asha Krishnan | H39: Consumer | I39: India | J39: Thiruvananthapuram | K39: Kerala | L39: West | M39: 560001 | N39: P-162 | O39: Clothing | P39: Shoes | Q39: Running Shoes | R39: 15884.13 | S39: 5 | T39: 0 | U39: 4002
A40: 1683 | B40: ORD-2024-00683 | C40: 45375 | D40: 45381 | E40: Same Day | F40: CUST-1056 | G40: Ananya Menon | H40: Consumer | I40: India | J40: Thiruvananthapuram | K40: Kerala | L40: east | M40: 673001 | N40: P-552 | P40: Laptops | Q40: Dell Inspiron 15 | R40: 45848.58 | S40: 1 | T40: 0.15 | U40: 467.53
A41: 1686 | B41: ORD-2024-00686 | C41: 45640 | D41: 45646 | E41: Standard Class | F41: CUST-1051 | G41: Meera Joseph | H41: Consumer | I41: India | J41: Ahmedabad | K41: Gujarat | L41: South | M41: 110001 | N41: P-431 | O41: Office supplies | P41: Art | Q41: Marker Set | R41: 694.72 | S41: 2 | T41: 0.15 | U41: 59.85
...

Sheet cleaned data
A1: Row ID | B1: Order ID | C1: Order Date | D1: Ship Date | E1: Ship Mode | F1: Customer ID | G1: Customer Name | H1: Segment | I1: Country | J1: City | K1: State | L1: Region | M1: Postal Code | N1: Product ID | O1: Category | P1: Sub-Category | Q1: Product Name | R1: Sales | S1: Quantity | T1: Discount | U1: Profit | V1: Sales Check | W1: Quantity Check
A2: 1001 | B2: ORD-2024-00001 | C2: 45363 | D2: 45369 | E2: Standard Class | F2: CUST-1087 | G2: NIKHIL VARMA | H2: Consumer | I2: India | J2: Lucknow | K2: Uttar Pradesh | L2: South | M2: 600001 | N2: P-532 | O2: Electronics | P2: Mobiles | Q2: Samsung Galaxy A55 | R2: 63499.23 | S2: 2 | T2: 0.1 | U2: 3501.42 | V2: OK | W2: OK
A3: 1002 | B3: ORD-2024-00002 | C3: 45579 | D3: 45581 | E3: Same Day | F3: CUST-1029 | G3: SNEHA NAIR | H3: Consumer | I3: India | J3: Kozhikode | K3: Kerala | L3: North | M3: 110001 | N3: P-990 | O3: Electronics | P3: Laptops | Q3: Dell Inspiron 15 | R3: 53930.19 | S3: 1 | T3: 0 | U3: 6224.96 | V3: OK | W3: OK
A4: 1003 | B4: ORD-2024-00003 | C4: 45434 | D4: 45436 | E4: Second Class | F4: CUST-1098 | G4: MEERA JOSEPH | H4: Corporate | I4: India | J4: Kozhikode | K4: Kerala | L4: South | M4: 673001 | N4: P-489 | O4: Clothing | P4: Shoes | Q4: Running Shoes | R4: 9676.42 | S4: 4 | T4: 0.2 | U4: 961.45 | V4: OK | W4: OK
A5: 1004 | B5: ORD-2024-00004 | C5: 45527 | D5: 45532 | E5: Standard Class | F5: CUST-1119 | G5: AMAL THOMAS | H5: Corporate | I5: India | J5: Kochi | K5: Kerala | L5: South | M5: 600001 | N5: P-400 | O5: Furniture | P5: Tables | Q5: Study Table | R5: 20072.74 | S5: 3 | T5: 0 | U5: 3799.65 | V5: OK | W5: OK
A6: 1005 | B6: ORD-2024-00005 | C6: 45652 | D6: 45653 | E6: Standard Class | F6: CUST-1085 | G6: FATHIMA ALI | H6: Corporate | I6: India | J6: Hyderabad | K6: Telangana | L6: North | M6: 673001 | N6: P-975 | O6: Office Supplies | P6: Art | Q6: Marker Set | R6: 1737.67 | S6: 5 | T6: 0.1 | U6: 258.99 | V6: OK | W6: OK
A7: 1006 | B7: ORD-2024-00006 | C7: 45375 | D7: 45378 | E7: First Class | F7: CUST-1027 | G7: ADIL KHAN | H7: Consumer | I7: India | J7: Bengaluru | K7: Karnataka | L7: North | M7: 400001 | N7: P-799 | O7: Home Appliances | P7: Kitchen | Q7: Electric Kettle | R7: 3249.99 | S7: 2 | T7: 0.2 | U7: -130 | V7: OK | W7: OK
A8: 1007 | B8: ORD-2024-00007 | C8: 45375 | D8: 45379 | E8: Same Day | F8: CUST-1035 | G8: MUHAMMED SHAFI | H8: Corporate | I8: India | J8: Lucknow | K8: Uttar Pradesh | L8: West | M8: 400001 | N8: P-432 | O8: Electronics | P8: Mobiles | Q8: Samsung Galaxy A55 | R8: 34123.38 | S8: 1 | T8: 0.1 | U8: 1314.69 | V8: OK | W8: OK
A9: 1008 | B9: ORD-2024-00008 | C9: 45453 | D9: 45457 | E9: First Class | F9: CUST-1009 | G9: FATHIMA ALI | H9: Corporate | I9: India | J9: Hyderabad | K9: Telangana | L9: North | M9: 682001 | N9: P-771 | O9: Clothing | P9: Shoes | Q9: Running Shoes | R9: 3037.09 | S9: 1 | T9: 0 | U9: 639.08 | V9: OK | W9: OK
A10: 1009 | B10: ORD-2024-00009 | C10: 45427 | D10: 45429 | E10: Second Class | F10: CUST-1096 | G10: VISHNU RAJ | H10: Home Office | I10: India | J10: Ahmedabad | K10: Gujarat | L10: North | M10: 400001 | N10: P-698 | O10: Furniture | P10: Bookcases | Q10: Wooden Bookshelf | R10: 17668.7 | S10: 3 | T10: 0.05 | U10: 2280.64 | V10: OK | W10: OK
A11: 1010 | B11: ORD-2024-00010 | C11: 45552 | D11: 45556 | E11: Standard Class | F11: CUST-1097 | G11: AARAV NAIR | H11: Corporate | I11: India | J11: Pune | K11: Maharashtra | L11: South | M11: 682001 | N11: P-742 | O11: Home Appliances | P11: Kitchen | Q11: Mixer Grinder | R11: 10900.01 | S11: 2 | T11: 0.05 | U11: 951.82 | V11: OK | W11: OK
A12: 1011 | B12: ORD-2024-00011 | C12: 45487 | D12: 45492 | E12: Same Day | F12: CUST-1068 | G12: ARJUN DAS | H12: Corporate | I12: India | J12: Thiruvananthapuram | K12: Kerala | L12: South | M12: 400001 | N12: P-838 | O12: Clothing | P12: Shoes | Q12: Running Shoes | R12: 7328.85 | S12: 3 | T12: 0.25 | U12: 525.68 | V12: OK | W12: OK
A13: 1012 | B13: ORD-2024-00012 | C13: 45349 | D13: 45352 | E13: Same Day | F13: CUST-1021 | G13: SNEHA NAIR | H13: Home Office | I13: India | J13: Kochi | K13: Kerala | L13: South | M13: 400001 | N13: P-996 | O13: Office Supplies | P13: Art | Q13: Marker Set | R13: 1175.56 | S13: 4 | T13: 0.2 | U13: 76.79 | V13: OK | W13: OK
... A751: 1750 | B751: ORD-2024-00750 | C751: 45295 | D751: 45297 | E751: Same Day | F751: CUST-1015 | G751: RIYA PAUL | H751: Consumer | I751: India | J751: Mumbai | K751: Maharashtra | L751: West | M751: 600001 | N751: P-612 | O751: Electronics | P751: Laptops | Q751: Dell Inspiron 15 | R751: 275399.02 | S751: 6 | T751: 0.1 | U751: 14644.34 | V751: OK | W751: OK

Sheet pivot analysis
A1: Category | B1: Sum of Sales | D1: Region | E1: Sum of Sales | G1: Segment | H1: Sum of Profit | J1: Category | K1: Sum of Quantity | M1: Row Labels | N1: Count of Order ID
A2: Clothing | B2: 757185.97 | D2: East | E2: 4836233.8 | G2: Consumer | H2: 509235.27 | J2: Clothing | K2: 355 | M2: ORD-2024-00001 | N2: 1
A3: Electronics | B3: 13711838 | D3: North | E3: 3972680.5 | G3: Corporate | H3: 293021.4 | J3: Electronics | K3: 600 | M3: ORD-2024-00002 | N3: 1
A4: Furniture | B4: 3314942.6 | D4: South | E4: 4957758.6 | G4: Home Office | H4: 155047.87 | J4: Furniture | K4: 520 | M4: ORD-2024-00003 | N4: 1
A5: Home Appliances | B5: 773774.1 | D5: West | E5: 6127562.8 | G5: Grand Total | H5: 957304.54 | J5: Home Appliances | K5: 206 | M5: ORD-2024-00004 | N5: 1
A6: Office Supplies | B6: 1336494.9 | D6: Grand Total | E6: 19894236 | J6: Office Supplies | K6: 696 | M6: ORD-2024-00005 | N6: 1
A7: Grand Total | B7: 19894236 | J7: Grand Total | K7: 2377 | M7: ORD-2024-00006 | N7: 1
H8: =GETPIVOTDATA("Profit",$G$1) -> 957304.54 | M8: ORD-2024-00007 | N8: 1
K9: =GETPIVOTDATA("Quantity",$J$1) -> 2377 | M9: ORD-2024-00008 | N9: 1
B10: =GETPIVOTDATA("Sales",$A$1) -> 19894236 | M10: ORD-2024-00009 | N10: 1
M11: ORD-2024-00010 | N11: 1
M12: ORD-2024-00011 | N12: 1
M13: ORD-2024-00012 | N13: 1
M14: ORD-2024-00013 | N14: 1
M15: ORD-2024-00014 | N15: 1
M16: ORD-2024-00015 | N16: 1
M17: ORD-2024-00016 | N17: 1
M18: ORD-2024-00017 | N18: 1
M19: ORD-2024-00018 | N19: 1
M20: ORD-2024-00019 | N20: 1
M21: ORD-2024-00020 | N21: 1
M22: ORD-2024-00021 | N22: 1
... M752: Grand Total | N752: 750
N754: =GETPIVOTDATA("Order ID",$M$1) -> 750

Sheet Dashboard

Sheet Retail Domain & KPIs
A1: Retail Business Domain & KPI Definitions
A3: KPI | B3: Formula / Calculation | C3: Business Meaning
A4: Total Sales | B4: SUM(Sales) | C4: Total revenue generated
A5: Total Profit | B5: SUM(Profit) | C5: Total profit earned
A6: Profit Margin | B6: Total Profit / Total Sales | C6: Profit earned as a percentage of sales
A7: Average Order Value (AOV) | B7: Total Sales / Number of Orders | C7: Average sales value per order
A8: Quantity Sold | B8: SUM(Quantity) | C8: Total number of units sold
A10: Analysis | B10: Purpose
A11: Sales by Product Category | B11: Compare revenue across categories
A12: Sales by Region | B12: Compare regional performance
A13: Customer Segment Performance | B13: Compare Consumer, Corporate, etc.
A14: Sales Trend Over Time | B14: Understand sales changes over dates
A15: Discount vs Profit | B15: Understand how discounts affect profitability

Sheet Basic Analysis
A1: Category | B1: Total Sales | D1: Region | E1: Total Sales | G1: Segment | H1: Total Profit | J1: Category | K1: Total Quantity
A2: Electronics | B2: =SUMIF('Raw Data'!O:O,A2,'Raw Data'!R:R) -> 9604965.3 | D2: North | E2: =SUMIF('Raw Data'!L:L,D2,'Raw Data'!R:R) -> 2622001.2 | G2: Consumer | H2: =SUMIF('Raw Data'!H:H,G2,'Raw Data'!U:U) -> 521751.35 | J2: Electronics | K2: =SUMIF('Raw Data'!O:O,J2,'Raw Data'!S:S) -> 500
A3: Clothing | B3: =SUMIF('Raw Data'!O:O,A3,'Raw Data'!R:R) -> 684144.42 | D3: East | E3: =SUMIF('Raw Data'!L:L,D3,'Raw Data'!R:R) -> 4332640.8 | G3: Corporate | H3: =SUMIF('Raw Data'!H:H,G3,'Raw Data'!U:U) -> 256305.35 | J3: Clothing | K3: =SUMIF('Raw Data'!O:O,J3,'Raw Data'!S:S) -> 312
A4: Furniture | B4: =SUMIF('Raw Data'!O:O,A4,'Raw Data'!R:R) -> 2996961 | D4: South | E4: =SUMIF('Raw Data'!L:L,D4,'Raw Data'!R:R) -> 3618500.3 | G4: Home Office | H4: =SUMIF('Raw Data'!H:H,G4,'Raw Data'!U:U) -> 138780.13 | J4: Furniture | K4: =SUMIF('Raw Data'!O:O,J4,'Raw Data'!S:S) -> 472
A5: Office Supplies | B5: =SUMIF('Raw Data'!O:O,A5,'Raw Data'!R:R) -> 293052.82 | D5: West | E5: =SUMIF('Raw Data'!L:L,D5,'Raw Data'!R:R) -> 4295165.5 | J5: Office Supplies | K5: =SUMIF('Raw Data'!O:O,J5,'Raw Data'!S:S) -> 607
A6: Home Appliances | B6: =SUMIF('Raw Data'!O:O,A6,'Raw Data'!R:R) -> 647905.26 | J6: Home Appliances | K6: =SUMIF('Raw Data'!O:O,J6,'Raw Data'!S:S) -> 174
